Workbook

Sheet Inputs
A1: Current age | B1: 49
A2: Partner's current age | B2: 44
A3: Planned retirement age | B3: 68
A4: Your expected lifespan | B4: 95
A5: Partner's expected lifespan | B5: 99
A6: Current home value | B6: 700000
A7: Outstanding mortgage | B7: 500000
A8: Annual mortgage rate | B8: 0.05
A9: Years left on mortgage | B9: 25.3
A10: Current Cash/Savings | B10: 55000
A11: Stock portfolio | B11: 62000
A12: Annual salary | B12: 140000
... A19: Safe withdrawal rate | B19: 0.04
A20: Current Superannuation Balance | B20: =300000 -> 300000
A21: Superannuation growth % | B21: 0.09
A22: Age Pension full annual (couple) | B22: 46202
A23: Age Pension assets threshold (homeowner couple) | B23: 481500
A24: Age Pension income threshold (annual) | B24: 8736

Sheet Calculations
A1: Years to Retirement | B1: =Inputs!B3-Inputs!B1 -> 19
A2: Years in Retirement | B2: =Inputs!B4-Inputs!B3 -> 27
A3: Current Combined Salary | B3: =Inputs!B12+Inputs!B13 -> 176000
A4: Annual Savings Contribution | B4: =(Inputs!B12+Inputs!B13)*Inputs!B14 -> 17600
A5: Future Value of Current Savings | B5: =FV(Inputs!B17, Calculations!B1, 0, -Inputs!B10) -> 198909.01
A6: Future Value of Current Stock Portfolio | B6: =FV(Inputs!B17, Calculations!B1, 0, -Inputs!B11) -> 224224.71
A7: Future Value of Monthly Stock Contributions | B7: =FV(Inputs!B17/12, Calculations!B1*12, -Inputs!B15, 0, 1) -> 477016.93
A8: Total Future Savings | B8: =Calculations!B5+Calculations!B6+Calculations!B7 -> 900150.65
A9: Mortgage Balance at Retirement | B9: =FV(Inputs!B8/12, Inputs!B9*12-Calculations!B1*12, -PMT(Inputs!B8/12, Inputs!B9*12, Inputs!B7), -Inputs!B7) -> 427112.67
A10: Home Value at Retirement | B10: =FV(Inputs!B16, Calculations!B1, 0, -Inputs!B6) -> 1227454.2
A11: Net Home Equity at Retirement | B11: =Calculations!B10-Calculations!B9 -> 800341.57
A12: Required Annual Income (ASFA, inflation adjusted) | B12: =73031*(1+Inputs!B16)^Calculations!B1 -> 128060.3
A13: Required Retirement Corpus | B13: =Calculations!B12*Calculations!B2 -> 3457628.1
A14: Pension Assets Test | B14: =MAX(0, Inputs!B22 - ((MAX(0, Calculations!B8-Inputs!B23)/1000)*3*26)) -> 13547.249
A15: Pension Income Test | B15: =MAX(0, Inputs!B22 - (MAX(0, Calculations!B12-Inputs!B24)*0.5)) -> 0
A16: Estimated Pension | B16: =MIN(Calculations!B14, Calculations!B15) -> 0

Sheet Projection
A1: Year | B1: Age (You) | C1: Age (Partner) | D1: Start Balance | E1: Contributions | F1: Investment Growth | G1: Withdrawals | H1: Pension | I1: End Balance | J1: Required Income
A2: 2025 | B2: =Inputs!B1 -> 49 | C2: =Inputs!B2 -> 44 | D2: =Inputs!B10+Inputs!B11+Inputs!B20 -> 417000 | E2: =(Inputs!B12+Inputs!B13)*Inputs!B14+Inputs!B15*12+Inputs!B12*0.11 -> 45000 | F2: =(D2+E2)*Inputs!B17 -> 32340 | G2: 0 | H2: 0 | I2: =D2+E2+F2-G2+H2 -> 494340 | J2: =73031*(1+Inputs!B16)^(A2-2025) -> 73031
A3: =A2+1 -> 2026 | B3: =B2+1 -> 50 | C3: =C2+1 -> 45 | D3: =I2 -> 494340 | E3: =IF(B2<Inputs!B3,(Inputs!B12+Inputs!B13)*Inputs!B14+Inputs!B15*12+Inputs!B12*0.11,0) -> 45000 | F3: =(D3+E3)*Inputs!B17 -> 37753.8 | G3: =IF(B2>=Inputs!B3, J2-H2, 0) -> 0 | H3: =IF(B2>=Inputs!B3, Calculations!B16, 0) -> 0 | I3: =D3+E3+F3-G3+H3 -> 577093.8 | J3: =73031*(1+Inputs!B16)^(A3-2025) -> 75221.93
A4: =A3+1 -> 2027 | B4: =B3+1 -> 51 | C4: =C3+1 -> 46 | D4: =I3 -> 577093.8 | E4: =IF(B3<Inputs!B3,(Inputs!B12+Inputs!B13)*Inputs!B14+Inputs!B15*12+Inputs!B12*0.11,0) -> 45000 | F4: =(D4+E4)*Inputs!B17 -> 43546.566 | G4: =IF(B3>=Inputs!B3, J3-H3, 0) -> 0 | H4: =IF(B3>=Inputs!B3, Calculations!B16, 0) -> 0 | I4: =D4+E4+F4-G4+H4 -> 665640.37 | J4: =73031*(1+Inputs!B16)^(A4-2025) -> 77478.588
A5: =A4+1 -> 2028 | B5: =B4+1 -> 52 | C5: =C4+1 -> 47 | D5: =I4 -> 665640.37 | E5: =IF(B4<Inputs!B3,(Inputs!B12+Inputs!B13)*Inputs!B14+Inputs!B15*12+Inputs!B12*0.11,0) -> 45000 | F5: =(D5+E5)*Inputs!B17 -> 49744.826 | G5: =IF(B4>=Inputs!B3, J4-H4, 0) -> 0 | H5: =IF(B4>=Inputs!B3, Calculations!B16, 0) -> 0 | I5: =D5+E5+F5-G5+H5 -> 760385.19 | J5: =73031*(1+Inputs!B16)^(A5-2025) -> 79802.946
A6: =A5+1 -> 2029 | B6: =B5+1 -> 53 | C6: =C5+1 -> 48 | D6: =I5 -> 760385.19 | E6: =IF(B5<Inputs!B3,(Inputs!B12+Inputs!B13)*Inputs!B14+Inputs!B15*12+Inputs!B12*0.11,0) -> 45000 | F6: =(D6+E6)*Inputs!B17 -> 56376.963 | G6: =IF(B5>=Inputs!B3, J5-H5, 0) -> 0 | H6: =IF(B5>=Inputs!B3, Calculations!B16, 0) -> 0 | I6: =D6+E6+F6-G6+H6 -> 861762.16 | J6: =73031*(1+Inputs!B16)^(A6-2025) -> 82197.034
A7: =A6+1 -> 2030 | B7: =B6+1 -> 54 | C7: =C6+1 -> 49 | D7: =I6 -> 861762.16 | E7: =IF(B6<Inputs!B3,(Inputs!B12+Inputs!B13)*Inputs!B14+Inputs!B15*12+Inputs!B12*0.11,0) -> 45000 | F7: =(D7+E7)*Inputs!B17 -> 63473.351 | G7: =IF(B6>=Inputs!B3, J6-H6, 0) -> 0 | H7: =IF(B6>=Inputs!B3, Calculations!B16, 0) -> 0 | I7: =D7+E7+F7-G7+H7 -> 970235.51 | J7: =73031*(1+Inputs!B16)^(A7-2025) -> 84662.945
A8: =A7+1 -> 2031 | B8: =B7+1 -> 55 | C8: =C7+1 -> 50 | D8: =I7 -> 970235.51 | E8: =IF(B7<Inputs!B3,(Inputs!B12+Inputs!B13)*Inputs!B14+Inputs!B15*12+Inputs!B12*0.11,0) -> 45000 | F8: =(D8+E8)*Inputs!B17 -> 71066.485 | G8: =IF(B7>=Inputs!B3, J7-H7, 0) -> 0 | H8: =IF(B7>=Inputs!B3, Calculations!B16, 0) -> 0 | I8: =D8+E8+F8-G8+H8 -> 1086302 | J8: =73031*(1+Inputs!B16)^(A8-2025) -> 87202.833
A9: =A8+1 -> 2032 | B9: =B8+1 -> 56 | C9: =C8+1 -> 51 | D9: =I8 -> 1086302 | E9: =IF(B8<Inputs!B3,(Inputs!B12+Inputs!B13)*Inputs!B14+Inputs!B15*12+Inputs!B12*0.11,0) -> 45000 | F9: =(D9+E9)*Inputs!B17 -> 79191.139 | G9: =IF(B8>=Inputs!B3, J8-H8, 0) -> 0 | H9: =IF(B8>=Inputs!B3, Calculations!B16, 0) -> 0 | I9: =D9+E9+F9-G9+H9 -> 1210493.1 | J9: =73031*(1+Inputs!B16)^(A9-2025) -> 89818.918
A10: =A9+1 -> 2033 | B10: =B9+1 -> 57 | C10: =C9+1 -> 52 | D10: =I9 -> 1210493.1 | E10: =IF(B9<Inputs!B3,(Inputs!B12+Inputs!B13)*Inputs!B14+Inputs!B15*12+Inputs!B12*0.11,0) -> 45000 | F10: =(D10+E10)*Inputs!B17 -> 87884.519 | G10: =IF(B9>=Inputs!B3, J9-H9, 0) -> 0 | H10: =IF(B9>=Inputs!B3, Calculations!B16, 0) -> 0 | I10: =D10+E10+F10-G10+H10 -> 1343377.6 | J10: =73031*(1+Inputs!B16)^(A10-2025) -> 92513.486
A11: =A10+1 -> 2034 | B11: =B10+1 -> 58 | C11: =C10+1 -> 53 | D11: =I10 -> 1343377.6 | E11: =IF(B10<Inputs!B3,(Inputs!B12+Inputs!B13)*Inputs!B14+Inputs!B15*12+Inputs!B12*0.11,0) -> 45000 | F11: =(D11+E11)*Inputs!B17 -> 97186.435 | G11: =IF(B10>=Inputs!B3, J10-H10, 0) -> 0 | H11: =IF(B10>=Inputs!B3, Calculations!B16, 0) -> 0 | I11: =D11+E11+F11-G11+H11 -> 1485564.1 | J11: =73031*(1+Inputs!B16)^(A11-2025) -> 95288.89
A12: =A11+1 -> 2035 | B12: =B11+1 -> 59 | C12: =C11+1 -> 54 | D12: =I11 -> 1485564.1 | E12: =IF(B11<Inputs!B3,(Inputs!B12+Inputs!B13)*Inputs!B14+Inputs!B15*12+Inputs!B12*0.11,0) -> 45000 | F12: =(D12+E12)*Inputs!B17 -> 107139.49 | G12: =IF(B11>=Inputs!B3, J11-H11, 0) -> 0 | H12: =IF(B11>=Inputs!B3, Calculations!B16, 0) -> 0 | I12: =D12+E12+F12-G12+H12 -> 1637703.6 | J12: =73031*(1+Inputs!B16)^(A12-2025) -> 98147.557
A13: =A12+1 -> 2036 | B13: =B12+1 -> 60 | C13: =C12+1 -> 55 | D13: =I12 -> 1637703.6 | E13: =IF(B12<Inputs!B3,(Inputs!B12+Inputs!B13)*Inputs!B14+Inputs!B15*12+Inputs!B12*0.11,0) -> 45000 | F13: =(D13+E13)*Inputs!B17 -> 117789.25 | G13: =IF(B12>=Inputs!B3, J12-H12, 0) -> 0 | H13: =IF(B12>=Inputs!B3, Calculations!B16, 0) -> 0 | I13: =D13+E13+F13-G13+H13 -> 1800492.8 | J13: =73031*(1+Inputs!B16)^(A13-2025) -> 101091.98
A14: =A13+1 -> 2037 | B14: =B13+1 -> 61 | C14: =C13+1 -> 56 | D14: =I13 -> 1800492.8 | E14: =IF(B13<Inputs!B3,(Inputs!B12+Inputs!B13)*Inputs!B14+Inputs!B15*12+Inputs!B12*0.11,0) -> 45000 | F14: =(D14+E14)*Inputs!B17 -> 129184.5 | G14: =IF(B13>=Inputs!B3, J13-H13, 0) -> 0 | H14: =IF(B13>=Inputs!B3, Calculations!B16, 0) -> 0 | I14: =D14+E14+F14-G14+H14 -> 1974677.3 | J14: =73031*(1+Inputs!B16)^(A14-2025) -> 104124.74
A15: =A14+1 -> 2038 | B15: =B14+1 -> 62 | C15: =C14+1 -> 57 | D15: =I14 -> 1974677.3 | E15: =IF(B14<Inputs!B3,(Inputs!B12+Inputs!B13)*Inputs!B14+Inputs!B15*12+Inputs!B12*0.11,0) -> 45000 | F15: =(D15+E15)*Inputs!B17 -> 141377.41 | G15: =IF(B14>=Inputs!B3, J14-H14, 0) -> 0 | H15: =IF(B14>=Inputs!B3, Calculations!B16, 0) -> 0 | I15: =D15+E15+F15-G15+H15 -> 2161054.7 | J15: =73031*(1+Inputs!B16)^(A15-2025) -> 107248.49
A16: =A15+1 -> 2039 | B16: =B15+1 -> 63 | C16: =C15+1 -> 58 | D16: =I15 -> 2161054.7 | E16: =IF(B15<Inputs!B3,(Inputs!B12+Inputs!B13)*Inputs!B14+Inputs!B15*12+Inputs!B12*0.11,0) -> 45000 | F16: =(D16+E16)*Inputs!B17 -> 154423.83 | G16: =IF(B15>=Inputs!B3, J15-H15, 0) -> 0 | H16: =IF(B15>=Inputs!B3, Calculations!B16, 0) -> 0 | I16: =D16+E16+F16-G16+H16 -> 2360478.6 | J16: =73031*(1+Inputs!B16)^(A16-2025) -> 110465.94
A17: =A16+1 -> 2040 | B17: =B16+1 -> 64 | C17: =C16+1 -> 59 | D17: =I16 -> 2360478.6 | E17: =IF(B16<Inputs!B3,(Inputs!B12+Inputs!B13)*Inputs!B14+Inputs!B15*12+Inputs!B12*0.11,0) -> 45000 | F17: =(D17+E17)*Inputs!B17 -> 168383.5 | G17: =IF(B16>=Inputs!B3, J16-H16, 0) -> 0 | H17: =IF(B16>=Inputs!B3, Calculations!B16, 0) -> 0 | I17: =D17+E17+F17-G17+H17 -> 2573862.1 | J17: =73031*(1+Inputs!B16)^(A17-2025) -> 113779.92
A18: =A17+1 -> 2041 | B18: =B17+1 -> 65 | C18: =C17+1 -> 60 | D18: =I17 -> 2573862.1 | E18: =IF(B17<Inputs!B3,(Inputs!B12+Inputs!B13)*Inputs!B14+Inputs!B15*12+Inputs!B12*0.11,0) -> 45000 | F18: =(D18+E18)*Inputs!B17 -> 183320.34 | G18: =IF(B17>=Inputs!B3, J17-H17, 0) -> 0 | H18: =IF(B17>=Inputs!B3, Calculations!B16, 0) -> 0 | I18: =D18+E18+F18-G18+H18 -> 2802182.4 | J18: =73031*(1+Inputs!B16)^(A18-2025) -> 117193.32
A19: =A18+1 -> 2042 | B19: =B18+1 -> 66 | C19: =C18+1 -> 61 | D19: =I18 -> 2802182.4 | E19: =IF(B18<Inputs!B3,(Inputs!B12+Inputs!B13)*Inputs!B14+Inputs!B15*12+Inputs!B12*0.11,0) -> 45000 | F19: =(D19+E19)*Inputs!B17 -> 199302.77 | G19: =IF(B18>=Inputs!B3, J18-H18, 0) -> 0 | H19: =IF(B18>=Inputs!B3, Calculations!B16, 0) -> 0 | I19: =D19+E19+F19-G19+H19 -> 3046485.2 | J19: =73031*(1+Inputs!B16)^(A19-2025) -> 120709.12
A20: =A19+1 -> 2043 | B20: =B19+1 -> 67 | C20: =C19+1 -> 62 | D20: =I19 -> 3046485.2 | E20: =IF(B19<Inputs!B3,(Inputs!B12+Inputs!B13)*Inputs!B14+Inputs!B15*12+Inputs!B12*0.11,0) -> 45000 | F20: =(D20+E20)*Inputs!B17 -> 216403.96 | G20: =IF(B19>=Inputs!B3, J19-H19, 0) -> 0 | H20: =IF(B19>=Inputs!B3, Calculations!B16, 0) -> 0 | I20: =D20+E20+F20-G20+H20 -> 3307889.1 | J20: =73031*(1+Inputs!B16)^(A20-2025) -> 124330.39
A21: =A20+1 -> 2044 | B21: =B20+1 -> 68 | C21: =C20+1 -> 63 | D21: =I20 -> 3307889.1 | E21: =IF(B20<Inputs!B3,(Inputs!B12+Inputs!B13)*Inputs!B14+Inputs!B15*12+Inputs!B12*0.11,0) -> 45000 | F21: =(D21+E21)*Inputs!B17 -> 234702.24 | G21: =IF(B20>=Inputs!B3, J20-H20, 0) -> 0 | H21: =IF(B20>=Inputs!B3, Calculations!B16, 0) -> 0 | I21: =D21+E21+F21-G21+H21 -> 3587591.4 | J21: =73031*(1+Inputs!B16)^(A21-2025) -> 128060.3
A22: =A21+1 -> 2045 | B22: =B21+1 -> 69 | C22: =C21+1 -> 64 | D22: =I21 -> 3587591.4 | E22: =IF(B21<Inputs!B3,(Inputs!B12+Inputs!B13)*Inputs!B14+Inputs!B15*12+Inputs!B12*0.11,0) -> 0 | F22: =(D22+E22)*Inputs!B17 -> 251131.4 | G22: =IF(B21>=Inputs!B3, J21-H21, 0) -> 128060.3 | H22: =IF(B21>=Inputs!B3, Calculations!B16, 0) -> 0 | I22: =D22+E22+F22-G22+H22 -> 3710662.5 | J22: =73031*(1+Inputs!B16)^(A22-2025) -> 131902.11
A23: =A22+1 -> 2046 | B23: =B22+1 -> 70 | C23: =C22+1 -> 65 | D23: =I22 -> 3710662.5 | E23: =IF(B22<Inputs!B3,(Inputs!B12+Inputs!B13)*Inputs!B14+Inputs!B15*12+Inputs!B12*0.11,0) -> 0 | F23: =(D23+E23)*Inputs!B17 -> 259746.37 | G23: =IF(B22>=Inputs!B3, J22-H22, 0) -> 131902.11 | H23: =IF(B22>=Inputs!B3, Calculations!B16, 0) -> 0 | I23: =D23+E23+F23-G23+H23 -> 3838506.7 | J23: =73031*(1+Inputs!B16)^(A23-2025) -> 135859.17
A24: =A23+1 -> 2047 | B24: =B23+1 -> 71 | C24: =C23+1 -> 66 | D24: =I23 -> 3838506.7 | E24: =IF(B23<Inputs!B3,(Inputs!B12+Inputs!B13)*Inputs!B14+Inputs!B15*12+Inputs!B12*0.11,0) -> 0 | F24: =(D24+E24)*Inputs!B17 -> 268695.47 | G24: =IF(B23>=Inputs!B3, J23-H23, 0) -> 135859.17 | H24: =IF(B23>=Inputs!B3, Calculations!B16, 0) -> 0 | I24: =D24+E24+F24-G24+H24 -> 3971343 | J24: =73031*(1+Inputs!B16)^(A24-2025) -> 139934.95
A25: =A24+1 -> 2048 | B25: =B24+1 -> 72 | C25: =C24+1 -> 67 | D25: =I24 -> 3971343 | E25: =IF(B24<Inputs!B3,(Inputs!B12+Inputs!B13)*Inputs!B14+Inputs!B15*12+Inputs!B12*0.11,0) -> 0 | F25: =(D25+E25)*Inputs!B17 -> 277994.01 | G25: =IF(B24>=Inputs!B3, J24-H24, 0) -> 139934.95 | H25: =IF(B24>=Inputs!B3, Calculations!B16, 0) -> 0 | I25: =D25+E25+F25-G25+H25 -> 4109402.1 | J25: =73031*(1+Inputs!B16)^(A25-2025) -> 144133
A26: =A25+1 -> 2049 | B26: =B25+1 -> 73 | C26: =C25+1 -> 68 | D26: =I25 -> 4109402.1 | E26: =IF(B25<Inputs!B3,(Inputs!B12+Inputs!B13)*Inputs!B14+Inputs!B15*12+Inputs!B12*0.11,0) -> 0 | F26: =(D26+E26)*Inputs!B17 -> 287658.15 | G26: =IF(B25>=Inputs!B3, J25-H25, 0) -> 144133 | H26: =IF(B25>=Inputs!B3, Calculations!B16, 0) -> 0 | I26: =D26+E26+F26-G26+H26 -> 4252927.2 | J26: =73031*(1+Inputs!B16)^(A26-2025) -> 148456.99
A27: =A26+1 -> 2050 | B27: =B26+1 -> 74 | C27: =C26+1 -> 69 | D27: =I26 -> 4252927.2 | E27: =IF(B26<Inputs!B3,(Inputs!B12+Inputs!B13)*Inputs!B14+Inputs!B15*12+Inputs!B12*0.11,0) -> 0 | F27: =(D27+E27)*Inputs!B17 -> 297704.91 | G27: =IF(B26>=Inputs!B3, J26-H26, 0) -> 148456.99 | H27: =IF(B26>=Inputs!B3, Calculations!B16, 0) -> 0 | I27: =D27+E27+F27-G27+H27 -> 4402175.2 | J27: =73031*(1+Inputs!B16)^(A27-2025) -> 152910.7
A28: =A27+1 -> 2051 | B28: =B27+1 -> 75 | C28: =C27+1 -> 70 | D28: =I27 -> 4402175.2 | E28: =IF(B27<Inputs!B3,(Inputs!B12+Inputs!B13)*Inputs!B14+Inputs!B15*12+Inputs!B12*0.11,0) -> 0 | F28: =(D28+E28)*Inputs!B17 -> 308152.26 | G28: =IF(B27>=Inputs!B3, J27-H27, 0) -> 152910.7 | H28: =IF(B27>=Inputs!B3, Calculations!B16, 0) -> 0 | I28: =D28+E28+F28-G28+H28 -> 4557416.7 | J28: =73031*(1+Inputs!B16)^(A28-2025) -> 157498.02
A29: =A28+1 -> 2052 | B29: =B28+1 -> 76 | C29: =C28+1 -> 71 | D29: =I28 -> 4557416.7 | E29: =IF(B28<Inputs!B3,(Inputs!B12+Inputs!B13)*Inputs!B14+Inputs!B15*12+Inputs!B12*0.11,0) -> 0 | F29: =(D29+E29)*Inputs!B17 -> 319019.17 | G29: =IF(B28>=Inputs!B3, J28-H28, 0) -> 157498.02 | H29: =IF(B28>=Inputs!B3, Calculations!B16, 0) -> 0 | I29: =D29+E29+F29-G29+H29 -> 4718937.9 | J29: =73031*(1+Inputs!B16)^(A29-2025) -> 162222.96
A30: =A29+1 -> 2053 | B30: =B29+1 -> 77 | C30: =C29+1 -> 72 | D30: =I29 -> 4718937.9 | E30: =IF(B29<Inputs!B3,(Inputs!B12+Inputs!B13)*Inputs!B14+Inputs!B15*12+Inputs!B12*0.11,0) -> 0 | F30: =(D30+E30)*Inputs!B17 -> 330325.65 | G30: =IF(B29>=Inputs!B3, J29-H29, 0) -> 162222.96 | H30: =IF(B29>=Inputs!B3, Calculations!B16, 0) -> 0 | I30: =D30+E30+F30-G30+H30 -> 4887040.6 | J30: =73031*(1+Inputs!B16)^(A30-2025) -> 167089.65
A31: =A30+1 -> 2054 | B31: =B30+1 -> 78 | C31: =C30+1 -> 73 | D31: =I30 -> 4887040.6 | E31: =IF(B30<Inputs!B3,(Inputs!B12+Inputs!B13)*Inputs!B14+Inputs!B15*12+Inputs!B12*0.11,0) -> 0 | F31: =(D31+E31)*Inputs!B17 -> 342092.84 | G31: =IF(B30>=Inputs!B3, J30-H30, 0) -> 167089.65 | H31: =IF(B30>=Inputs!B3, Calculations!B16, 0) -> 0 | I31: =D31+E31+F31-G31+H31 -> 5062043.8 | J31: =73031*(1+Inputs!B16)^(A31-2025) -> 172102.34
A32: =A31+1 -> 2055 | B32: =B31+1 -> 79 | C32: =C31+1 -> 74 | D32: =I31 -> 5062043.8 | E32: =IF(B31<Inputs!B3,(Inputs!B12+Inputs!B13)*Inputs!B14+Inputs!B15*12+Inputs!B12*0.11,0) -> 0 | F32: =(D32+E32)*Inputs!B17 -> 354343.06 | G32: =IF(B31>=Inputs!B3, J31-H31, 0) -> 172102.34 | H32: =IF(B31>=Inputs!B3, Calculations!B16, 0) -> 0 | I32: =D32+E32+F32-G32+H32 -> 5244284.5 | J32: =73031*(1+Inputs!B16)^(A32-2025) -> 177265.41
A33: =A32+1 -> 2056 | B33: =B32+1 -> 80 | C33: =C32+1 -> 75 | D33: =I32 -> 5244284.5 | E33: =IF(B32<Inputs!B3,(Inputs!B12+Inputs!B13)*Inputs!B14+Inputs!B15*12+Inputs!B12*0.11,0) -> 0 | F33: =(D33+E33)*Inputs!B17 -> 367099.92 | G33: =IF(B32>=Inputs!B3, J32-H32, 0) -> 177265.41 | H33: =IF(B32>=Inputs!B3, Calculations!B16, 0) -> 0 | I33: =D33+E33+F33-G33+H33 -> 5434119 | J33: =73031*(1+Inputs!B16)^(A33-2025) -> 182583.37
A34: =A33+1 -> 2057 | B34: =B33+1 -> 81 | C34: =C33+1 -> 76 | D34: =I33 -> 5434119 | E34: =IF(B33<Inputs!B3,(Inputs!B12+Inputs!B13)*Inputs!B14+Inputs!B15*12+Inputs!B12*0.11,0) -> 0 | F34: =(D34+E34)*Inputs!B17 -> 380388.33 | G34: =IF(B33>=Inputs!B3, J33-H33, 0) -> 182583.37 | H34: =IF(B33>=Inputs!B3, Calculations!B16, 0) -> 0 | I34: =D34+E34+F34-G34+H34 -> 5631924 | J34: =73031*(1+Inputs!B16)^(A34-2025) -> 188060.87
A35: =A34+1 -> 2058 | B35: =B34+1 -> 82 | C35: =C34+1 -> 77 | D35: =I34 -> 5631924 | E35: =IF(B34<Inputs!B3,(Inputs!B12+Inputs!B13)*Inputs!B14+Inputs!B15*12+Inputs!B12*0.11,0) -> 0 | F35: =(D35+E35)*Inputs!B17 -> 394234.68 | G35: =IF(B34>=Inputs!B3, J34-H34, 0) -> 188060.87 | H35: =IF(B34>=Inputs!B3, Calculations!B16, 0) -> 0 | I35: =D35+E35+F35-G35+H35 -> 5838097.8 | J35: =73031*(1+Inputs!B16)^(A35-2025) -> 193702.69
A36: =A35+1 -> 2059 | B36: =B35+1 -> 83 | C36: =C35+1 -> 78 | D36: =I35 -> 5838097.8 | E36: =IF(B35<Inputs!B3,(Inputs!B12+Inputs!B13)*Inputs!B14+Inputs!B15*12+Inputs!B12*0.11,0) -> 0 | F36: =(D36+E36)*Inputs!B17 -> 408666.85 | G36: =IF(B35>=Inputs!B3, J35-H35, 0) -> 193702.69 | H36: =IF(B35>=Inputs!B3, Calculations!B16, 0) -> 0 | I36: =D36+E36+F36-G36+H36 -> 6053061.9 | J36: =73031*(1+Inputs!B16)^(A36-2025) -> 199513.78
A37: =A36+1 -> 2060 | B37: =B36+1 -> 84 | C37: =C36+1 -> 79 | D37: =I36 -> 6053061.9 | E37: =IF(B36<Inputs!B3,(Inputs!B12+Inputs!B13)*Inputs!B14+Inputs!B15*12+Inputs!B12*0.11,0) -> 0 | F37: =(D37+E37)*Inputs!B17 -> 423714.34 | G37: =IF(B36>=Inputs!B3, J36-H36, 0) -> 199513.78 | H37: =IF(B36>=Inputs!B3, Calculations!B16, 0) -> 0 | I37: =D37+E37+F37-G37+H37 -> 6277262.5 | J37: =73031*(1+Inputs!B16)^(A37-2025) -> 205499.19
A38: =A37+1 -> 2061 | B38: =B37+1 -> 85 | C38: =C37+1 -> 80 | D38: =I37 -> 6277262.5 | E38: =IF(B37<Inputs!B3,(Inputs!B12+Inputs!B13)*Inputs!B14+Inputs!B15*12+Inputs!B12*0.11,0) -> 0 | F38: =(D38+E38)*Inputs!B17 -> 439408.38 | G38: =IF(B37>=Inputs!B3, J37-H37, 0) -> 205499.19 | H38: =IF(B37>=Inputs!B3, Calculations!B16, 0) -> 0 | I38: =D38+E38+F38-G38+H38 -> 6511171.7 | J38: =73031*(1+Inputs!B16)^(A38-2025) -> 211664.16
A39: =A38+1 -> 2062 | B39: =B38+1 -> 86 | C39: =C38+1 -> 81 | D39: =I38 -> 6511171.7 | E39: =IF(B38<Inputs!B3,(Inputs!B12+Inputs!B13)*Inputs!B14+Inputs!B15*12+Inputs!B12*0.11,0) -> 0 | F39: =(D39+E39)*Inputs!B17 -> 455782.02 | G39: =IF(B38>=Inputs!B3, J38-H38, 0) -> 211664.16 | H39: =IF(B38>=Inputs!B3, Calculations!B16, 0) -> 0 | I39: =D39+E39+F39-G39+H39 -> 6755289.5 | J39: =73031*(1+Inputs!B16)^(A39-2025) -> 218014.09
A40: =A39+1 -> 2063 | B40: =B39+1 -> 87 | C40: =C39+1 -> 82 | D40: =I39 -> 6755289.5 | E40: =IF(B39<Inputs!B3,(Inputs!B12+Inputs!B13)*Inputs!B14+Inputs!B15*12+Inputs!B12*0.11,0) -> 0 | F40: =(D40+E40)*Inputs!B17 -> 472870.27 | G40: =IF(B39>=Inputs!B3, J39-H39, 0) -> 218014.09 | H40: =IF(B39>=Inputs!B3, Calculations!B16, 0) -> 0 | I40: =D40+E40+F40-G40+H40 -> 7010145.7 | J40: =73031*(1+Inputs!B16)^(A40-2025) -> 224554.51
...
